# 프로그램 오류 + 예외 처리

- 컴파일 에러(compile-time error) :  컴파일 할 때 발생하는 에러

- 런타임 에러(runtime error) :  실행 할 때 발생하는 에러

  1.  에러(error) :  프로그램 코드에 의해서 수습 될 수 없음
  2. 예외(exception) : 프로그램 코드에 의해서 수습 가능

- 논리적 에러(logical error) :  작성 의도와 다르게 동작

  

## 예외처리의 정의와 목적

-  정의 : 프로그램 실행 시 발생 할 수 있는 예외의 발생에 대비한 코드를 작성하는 것

- 목적 : 프로그램의 비정상 종료를 막고, 정상적인 실행상태를 유지하는 것

  ![예외 클래스의](https://user-images.githubusercontent.com/86362202/132617588-eb5aeb38-850c-485b-b2f5-e77f5bad7160.png)

  ​	

## Exception / RuntimeException

-  Exception 클래스들 : 사용자의 실수와 같은 외적인 요인에 의해 발생하는 예외

-  RuntimeException 클래스들 : 프로그래머의 실수로 발생하는 예외

  

![1234](https://user-images.githubusercontent.com/86362202/132617989-6c52e959-5de5-4b80-81ec-4d2899babce8.png)

## 예외 처리하기(exception handling) - try-catch문

정의 : 프로그램 실행 시 발생 할 수 있는 예외의 발생에 대비한 코드를 작성하는 것

목적 : 프로그램의 비정상 종료를 막고, 정상적인 실행 상태를 유지하는 것

```java
try { // 중괄호는 생략 불가
	// 예외가 발생할 가능성이 있는 문장들을 넣는다
} catch ( Exception1 e1) {
    // Exception1이 발생했을 경우, 이를 처리하기 위한 문장을 적는다
} catch ( Exception1 e2) {
    // Exception2이 발생했을 경우, 이를 처리하기 위한 문장을 적는다
} catch ( Exception1 eN) {
    // ExceptionN이 발생했을 경우, 이를 처리하기 위한 문장을 적는다
}
```

- try 블럭 내에서 예외가 발생한 경우

  1.  발생한 예외와 일치하는 catch 블럭이 있는지 확인한다

  2. 일치하는 catch블럭을 찾게 되면, 그 catch블럭 내의 문장들을 수행하고 전체 try-catch문을 빠져나가서

     그 다음 문장을 계속해서 수행한다. 만일 일치하는 catch블럭을 찾이 못했을 경우 예외는 처리되지 못함

  ```java
  class Ex8_4 {
  	public static void main(String args[]) {
  		System.out.println(1);			
  		System.out.println(2);
  		try { // 예외가 발생가능한 문장들 
  			System.out.println(3);
  			System.out.println(0/0); // 0으로 나눠서 고의로 arithmeticException 발생
  			System.out.println(4); 	// 실행되지 않는다.
  		} catch (ArithmeticException ae)	{ // 첫번째 catch문 검사 -> 일치 -> 실행
  			if (ae instanceof ArithmeticException) 
  				System.out.println("true");	
  			System.out.println("ArithmeticException");
  		} catch (Exception e){  // ArithmeticException을 제외한 모든 예외가 처리된다
  			System.out.println("Exception"); // Exception e : 모든 예외의 최고 조상
  		}	// try-catch의 끝
  		System.out.println(6);
  	}	// main메서드의 끝
  }
  ```

  

- try 블럭 내에서 예외가 발생하지 않을 경우

  : catch 블럭을 거치지 않고 전체 try-catch문을 빠져나가서 수행을 계속한다

